Workbook

Sheet Packages
A1: Cost, price and margin per client: change the yellow cells here and on Inputs
A3: Package | B3: Price (Rs) | C3: People | D3: Founder hours | E3: Tool cost (Rs, e.g. LGM) | F3: Claude cost (Rs) | G3: Setup (Rs) | H3: Gateway fee (Rs) | I3: GST (Rs) | J3: Fixed cost share (Rs) | K3: Founder time (Rs) | L3: Total cost (Rs) | M3: Profit (Rs) | N3: Margin % | O3: Cash margin % (excl. founder time)
A4: Sprint, 7 days | B4: 2499 | C4: 60 | D4: 5 | E4: 0 | F4: =C4*'Cost per prospect'!$C$13 -> 975.6384 | G4: =Inputs!$B$49*Inputs!$B$4 -> 44 | H4: =B4*Inputs!$B$5 -> 58.9764 | I4: =B4-B4/(1+Inputs!$B$7*Inputs!$B$6) -> 0 | J4: =Inputs!$B$9/Inputs!$B$10 -> 500 | K4: =D4*Inputs!$B$8 -> 2500 | L4: =SUM(E4:K4) -> 4078.6148 | M4: =B4-L4 -> -1579.6148 | N4: =M4/B4 -> -0.63209876 | O4: =(M4+K4)/B4 -> 0.3683014
A5: Standard, 14 days | B5: 3999 | C5: 120 | D5: 8 | E5: 0 | F5: =C5*'Cost per prospect'!$C$13 -> 1951.2768 | G5: =Inputs!$B$49*Inputs!$B$4 -> 44 | H5: =B5*Inputs!$B$5 -> 94.3764 | I5: =B5-B5/(1+Inputs!$B$7*Inputs!$B$6) -> 0 | J5: =Inputs!$B$9/Inputs!$B$10 -> 500 | K5: =D5*Inputs!$B$8 -> 4000 | L5: =SUM(E5:K5) -> 6589.6532 | M5: =B5-L5 -> -2590.6532 | N5: =M5/B5 -> -0.64782526 | O5: =(M5+K5)/B5 -> 0.35242481
A6: Full, 21 days | B6: 5499 | C6: 180 | D6: 11 | E6: 0 | F6: =C6*'Cost per prospect'!$C$13 -> 2926.9152 | G6: =Inputs!$B$49*Inputs!$B$4 -> 44 | H6: =B6*Inputs!$B$5 -> 129.7764 | I6: =B6-B6/(1+Inputs!$B$7*Inputs!$B$6) -> 0 | J6: =Inputs!$B$9/Inputs!$B$10 -> 500 | K6: =D6*Inputs!$B$8 -> 5500 | L6: =SUM(E6:K6) -> 9100.6916 | M6: =B6-L6 -> -3601.6916 | N6: =M6/B6 -> -0.6549721 | O6: =(M6+K6)/B6 -> 0.34520975
A7: Done-for-you (founding) | B7: 14999 | C7: 180 | D7: 16 | E7: 6160 | F7: =C7*'Cost per prospect'!$C$13 -> 2926.9152 | G7: =Inputs!$B$49*Inputs!$B$4 -> 44 | H7: =B7*Inputs!$B$5 -> 353.9764 | I7: =B7-B7/(1+Inputs!$B$7*Inputs!$B$6) -> 0 | J7: =Inputs!$B$9/Inputs!$B$10 -> 500 | K7: =D7*Inputs!$B$8 -> 8000 | L7: =SUM(E7:K7) -> 17984.892 | M7: =B7-L7 -> -2985.8916 | N7: =M7/B7 -> -0.19907271 | O7: =(M7+K7)/B7 -> 0.33429618
A8: Done-for-you (standard) | B8: 19999 | C8: 180 | D8: 16 | E8: 6160 | F8: =C8*'Cost per prospect'!$C$13 -> 2926.9152 | G8: =Inputs!$B$49*Inputs!$B$4 -> 44 | H8: =B8*Inputs!$B$5 -> 471.9764 | I8: =B8-B8/(1+Inputs!$B$7*Inputs!$B$6) -> 0 | J8: =Inputs!$B$9/Inputs!$B$10 -> 500 | K8: =D8*Inputs!$B$8 -> 8000 | L8: =SUM(E8:K8) -> 18102.892 | M8: =B8-L8 -> 1896.1084 | N8: =M8/B8 -> 0.094810161 | O8: =(M8+K8)/B8 -> 0.49483016
A11: Notes: Claude cost uses the step assumptions on Inputs (estimates until measured with the cost command). Done-for-you tool cost = one La Growth Machine Basic identity month (about $70). Founder hours are estimates.

Sheet Inputs
A1: Knock unit economics: change the yellow cells
A3: General
A4: USD to INR | B4: 88
A5: Payment gateway fee % (Razorpay 2% + 18% GST on fee) | B5: 0.0236
A6: Charge GST to client? (1 yes, 0 no; needed above Rs 20 lakh turnover) | B6: 0
A7: GST rate | B7: 0.18
A8: Founder or operator cost per hour (Rs) | B8: 500 | C8: what your time is worth
A9: Monthly fixed costs (Rs): Vercel Pro, domain, misc | B9: 2500
A10: Clients per month (to spread fixed costs) | B10: 5
A11: Model prices (USD per million tokens)
A12: Opus 5.5 input | B12: 4
A13: Opus 5.5 output | B13: 20
A14: Sonnet 5.5 input | B14: 2
A15: Sonnet 5.5 output | B15: 10
A16: Haiku 4.5 input | B16: 1
A17: Haiku 4.5 output | B17: 5
A18: Web search, USD per search | B18: 0.01
A19: Prompt caching saving on input (0 to 0.6) | B19: 0.3 | C19: repeated system prompts
A20: Per-prospect work (output includes thinking). Model: 1 Opus, 2 Sonnet, 3 Haiku
A21: Classify: input tokens | B21: 2000
A22: Classify: output tokens | B22: 300
A23: Classify: model | B23: 3
A24: Enrich: searches | B24: 2
A25: Enrich: input tokens | B25: 6000
A26: Enrich: output tokens | B26: 800
A27: Enrich: model | B27: 2
A28: Hooks: input tokens | B28: 6000
A29: Hooks: output tokens | B29: 1500
A30: Hooks: model | B30: 1
A31: Writers: count | B31: 3
A32: Writer: input tokens each | B32: 3000
... A38: Discovery searches per prospect (amortised) | B38: 1
A39: Conversation
A40: Share of prospects that get a follow-up | B40: 0.7
A41: Follow-up: input tokens | B41: 3000
A42: Follow-up: output tokens | B42: 500
A43: Follow-up: model | B43: 1
A44: Reply rate | B44: 0.3 | C44: replies per prospect
A45: Exchanges per reply | B45: 2
A46: Reply draft: input tokens | B46: 5000
...

Sheet Cost per prospect
A1: Claude cost per prospect
A3: Step | B3: USD | C3: INR
A4: Classify | B4: =(1)*(Inputs!$B$21*CHOOSE(Inputs!$B$23,Inputs!$B$12,Inputs!$B$14,Inputs!$B$16)*(1-Inputs!$B$19)+Inputs!$B$22*CHOOSE(Inputs!$B$23,Inputs!$B$13,Inputs!$B$15,Inputs!$B$17))/1000000 -> 0.0029 | C4: =B4*Inputs!$B$4 -> 0.2552
A5: Enrich (model) | B5: =(1)*(Inputs!$B$25*CHOOSE(Inputs!$B$27,Inputs!$B$12,Inputs!$B$14,Inputs!$B$16)*(1-Inputs!$B$19)+Inputs!$B$26*CHOOSE(Inputs!$B$27,Inputs!$B$13,Inputs!$B$15,Inputs!$B$17))/1000000 -> 0.0164 | C5: =B5*Inputs!$B$4 -> 1.4432
A6: Enrich (searches) | B6: =Inputs!$B$24*Inputs!$B$18 -> 0.02 | C6: =B6*Inputs!$B$4 -> 1.76
A7: Discovery searches | B7: =Inputs!$B$38*Inputs!$B$18 -> 0.01 | C7: =B7*Inputs!$B$4 -> 0.88
A8: Hooks | B8: =(1)*(Inputs!$B$28*CHOOSE(Inputs!$B$30,Inputs!$B$12,Inputs!$B$14,Inputs!$B$16)*(1-Inputs!$B$19)+Inputs!$B$29*CHOOSE(Inputs!$B$30,Inputs!$B$13,Inputs!$B$15,Inputs!$B$17))/1000000 -> 0.0468 | C8: =B8*Inputs!$B$4 -> 4.1184
A9: Writers | B9: =(Inputs!$B$31)*(Inputs!$B$32*CHOOSE(Inputs!$B$34,Inputs!$B$12,Inputs!$B$14,Inputs!$B$16)*(1-Inputs!$B$19)+Inputs!$B$33*CHOOSE(Inputs!$B$34,Inputs!$B$13,Inputs!$B$15,Inputs!$B$17))/1000000 -> 0.0306 | C9: =B9*Inputs!$B$4 -> 2.6928
A10: Judge | B10: =(1)*(Inputs!$B$35*CHOOSE(Inputs!$B$37,Inputs!$B$12,Inputs!$B$14,Inputs!$B$16)*(1-Inputs!$B$19)+Inputs!$B$36*CHOOSE(Inputs!$B$37,Inputs!$B$13,Inputs!$B$15,Inputs!$B$17))/1000000 -> 0.0272 | C10: =B10*Inputs!$B$4 -> 2.3936
A11: Follow-ups | B11: =(Inputs!$B$40)*(Inputs!$B$41*CHOOSE(Inputs!$B$43,Inputs!$B$12,Inputs!$B$14,Inputs!$B$16)*(1-Inputs!$B$19)+Inputs!$B$42*CHOOSE(Inputs!$B$43,Inputs!$B$13,Inputs!$B$15,Inputs!$B$17))/1000000 -> 0.01288 | C11: =B11*Inputs!$B$4 -> 1.13344
A12: Reply drafts | B12: =(Inputs!$B$44*Inputs!$B$45)*(Inputs!$B$46*CHOOSE(Inputs!$B$48,Inputs!$B$12,Inputs!$B$14,Inputs!$B$16)*(1-Inputs!$B$19)+Inputs!$B$47*CHOOSE(Inputs!$B$48,Inputs!$B$13,Inputs!$B$15,Inputs!$B$17))/1000000 -> 0.018 | C12: =B12*Inputs!$B$4 -> 1.584
A13: Total per prospect | B13: =SUM(B4:B12) -> 0.18478 | C13: =SUM(C4:C12) -> 16.26064
